+ module load cuda11.3/toolkit
+ '[' -z '' ']'
+ case "$-" in
+ __lmod_sh_dbg=x
+ '[' -n x ']'
+ set +x
Shell debugging temporarily silenced: export LMOD_SH_DBG_ON=1 for Lmod's output
Shell debugging restarted
+ unset __lmod_sh_dbg
+ return 0
+ source /var/scratch/tng204/anaconda3/etc/profile.d/conda.sh
++ export CONDA_EXE=/var/scratch/tng204/anaconda3/bin/conda
++ CONDA_EXE=/var/scratch/tng204/anaconda3/bin/conda
++ export _CE_M=
++ _CE_M=
++ export _CE_CONDA=
++ _CE_CONDA=
++ export CONDA_PYTHON_EXE=/var/scratch/tng204/anaconda3/bin/python
++ CONDA_PYTHON_EXE=/var/scratch/tng204/anaconda3/bin/python
++ '[' -z x ']'
+ conda activate mltrain
+ local cmd=activate
+ case "$cmd" in
+ __conda_activate activate mltrain
+ '[' -n '' ']'
+ local ask_conda
++ PS1=
++ __conda_exe shell.posix activate mltrain
++ '[' -n '' ']'
++ /var/scratch/tng204/anaconda3/bin/conda shell.posix activate mltrain
+ ask_conda='unset _CE_M
unset _CE_CONDA
PS1='\''(mltrain) '\''
export PATH='\''/cm/local/apps/cuda-driver/libs/current/bin:/cm/shared/apps/cuda11.3/toolkit/11.3.1/bin:/var/scratch/tng204/anaconda3/envs/mltrain/bin:/var/scratch/tng204/anaconda3/condabin:/home/tng204/.local/bin:/home/tng204/bin:/opt/ohpc/pub/mpi/libfabric/1.19.0/bin:/opt/ohpc/pub/mpi/ucx-ohpc/1.15.0/bin:/opt/ohpc/pub/libs/hwloc/bin:/opt/ohpc/pub/mpi/openmpi4-gnu12/4.1.6/bin:/opt/ohpc/pub/compiler/gcc/12.4.0/bin:/opt/ohpc/pub/utils/autotools/bin:/opt/ohpc/pub/bin:/usr/local/bin:/usr/bin:/usr/local/sbin:/usr/sbin:/cm/shared/package/reserve.slurm/bin'\''
export CONDA_SHLVL='\''2'\''
export CONDA_PROMPT_MODIFIER='\''(mltrain) '\''
export CONDA_EXE='\''/var/scratch/tng204/anaconda3/bin/conda'\''
export CONDA_PYTHON_EXE='\''/var/scratch/tng204/anaconda3/bin/python'\'''
+ eval 'unset _CE_M
unset _CE_CONDA
PS1='\''(mltrain) '\''
export PATH='\''/cm/local/apps/cuda-driver/libs/current/bin:/cm/shared/apps/cuda11.3/toolkit/11.3.1/bin:/var/scratch/tng204/anaconda3/envs/mltrain/bin:/var/scratch/tng204/anaconda3/condabin:/home/tng204/.local/bin:/home/tng204/bin:/opt/ohpc/pub/mpi/libfabric/1.19.0/bin:/opt/ohpc/pub/mpi/ucx-ohpc/1.15.0/bin:/opt/ohpc/pub/libs/hwloc/bin:/opt/ohpc/pub/mpi/openmpi4-gnu12/4.1.6/bin:/opt/ohpc/pub/compiler/gcc/12.4.0/bin:/opt/ohpc/pub/utils/autotools/bin:/opt/ohpc/pub/bin:/usr/local/bin:/usr/bin:/usr/local/sbin:/usr/sbin:/cm/shared/package/reserve.slurm/bin'\''
export CONDA_SHLVL='\''2'\''
export CONDA_PROMPT_MODIFIER='\''(mltrain) '\''
export CONDA_EXE='\''/var/scratch/tng204/anaconda3/bin/conda'\''
export CONDA_PYTHON_EXE='\''/var/scratch/tng204/anaconda3/bin/python'\'''
++ unset _CE_M
++ unset _CE_CONDA
++ PS1='(mltrain) '
++ export PATH=/cm/local/apps/cuda-driver/libs/current/bin:/cm/shared/apps/cuda11.3/toolkit/11.3.1/bin:/var/scratch/tng204/anaconda3/envs/mltrain/bin:/var/scratch/tng204/anaconda3/condabin:/home/tng204/.local/bin:/home/tng204/bin:/opt/ohpc/pub/mpi/libfabric/1.19.0/bin:/opt/ohpc/pub/mpi/ucx-ohpc/1.15.0/bin:/opt/ohpc/pub/libs/hwloc/bin:/opt/ohpc/pub/mpi/openmpi4-gnu12/4.1.6/bin:/opt/ohpc/pub/compiler/gcc/12.4.0/bin:/opt/ohpc/pub/utils/autotools/bin:/opt/ohpc/pub/bin:/usr/local/bin:/usr/bin:/usr/local/sbin:/usr/sbin:/cm/shared/package/reserve.slurm/bin
++ PATH=/cm/local/apps/cuda-driver/libs/current/bin:/cm/shared/apps/cuda11.3/toolkit/11.3.1/bin:/var/scratch/tng204/anaconda3/envs/mltrain/bin:/var/scratch/tng204/anaconda3/condabin:/home/tng204/.local/bin:/home/tng204/bin:/opt/ohpc/pub/mpi/libfabric/1.19.0/bin:/opt/ohpc/pub/mpi/ucx-ohpc/1.15.0/bin:/opt/ohpc/pub/libs/hwloc/bin:/opt/ohpc/pub/mpi/openmpi4-gnu12/4.1.6/bin:/opt/ohpc/pub/compiler/gcc/12.4.0/bin:/opt/ohpc/pub/utils/autotools/bin:/opt/ohpc/pub/bin:/usr/local/bin:/usr/bin:/usr/local/sbin:/usr/sbin:/cm/shared/package/reserve.slurm/bin
++ export CONDA_SHLVL=2
++ CONDA_SHLVL=2
++ export 'CONDA_PROMPT_MODIFIER=(mltrain) '
++ CONDA_PROMPT_MODIFIER='(mltrain) '
++ export CONDA_EXE=/var/scratch/tng204/anaconda3/bin/conda
++ CONDA_EXE=/var/scratch/tng204/anaconda3/bin/conda
++ export CONDA_PYTHON_EXE=/var/scratch/tng204/anaconda3/bin/python
++ CONDA_PYTHON_EXE=/var/scratch/tng204/anaconda3/bin/python
+ __conda_hashr
+ '[' -n '' ']'
+ '[' -n '' ']'
+ hash -r
+ cd /var/scratch/tng204/thesis/bachelor_thesis
+ python -c 'import torch; torch.cuda.empty_cache()'
++ head -n 1
++ scontrol show hostnames 'node[002-007,024-026,046-052]'
+ export MASTER_ADDR=node002
+ MASTER_ADDR=node002
+ export MASTER_PORT=29500
+ MASTER_PORT=29500
+ export WORLD_SIZE=16
+ WORLD_SIZE=16
+ export TORCH_DISTRIBUTED_TIMEOUT=1800
+ TORCH_DISTRIBUTED_TIMEOUT=1800
+ export NCCL_DEBUG=INFO
+ NCCL_DEBUG=INFO
+ export NCCL_IB_TIMEOUT=30
+ NCCL_IB_TIMEOUT=30
+ export NCCL_SOCKET_TIMEOUT=300
+ NCCL_SOCKET_TIMEOUT=300
+ echo '=== Distributed Training Configuration ==='
+ echo 'Master node: node002'
+ echo 'Master port: 29500'
+ echo 'World size: 16'
+ echo 'Job nodes: node[002-007,024-026,046-052]'
+ echo 'CUDA_VISIBLE_DEVICES: 0'
+ echo ========================================
+ mkdir -p logs
+ srun --kill-on-bad-exit=1 torchrun --nnodes=16 --nproc_per_node=1 --rdzv_id=25663 --rdzv_backend=c10d --rdzv_endpoint=node002:29500 --max_restarts=3 stable_char_transformer.py
Traceback (most recent call last):
  File "/var/scratch/tng204/thesis/bachelor_thesis/stable_char_transformer.py", line 1196, in <module>
    main()
  File "/var/scratch/tng204/thesis/bachelor_thesis/stable_char_transformer.py", line 1094, in main
    train_batches, start_batch = create_batches(train_data, local_batch_size, seq_length)
  File "/var/scratch/tng204/thesis/bachelor_thesis/stable_char_transformer.py", line 120, in create_batches
    chunk = chunk.view(batch_size, seq_length + 1)
RuntimeError: shape '[2, 1025]' is invalid for input of size 2049
Traceback (most recent call last):
  File "/var/scratch/tng204/thesis/bachelor_thesis/stable_char_transformer.py", line 1196, in <module>
    main()
  File "/var/scratch/tng204/thesis/bachelor_thesis/stable_char_transformer.py", line 1094, in main
    train_batches, start_batch = create_batches(train_data, local_batch_size, seq_length)
  File "/var/scratch/tng204/thesis/bachelor_thesis/stable_char_transformer.py", line 120, in create_batches
    chunk = chunk.view(batch_size, seq_length + 1)
RuntimeError: shape '[2, 1025]' is invalid for input of size 2049
Traceback (most recent call last):
  File "/var/scratch/tng204/thesis/bachelor_thesis/stable_char_transformer.py", line 1196, in <module>
    main()
  File "/var/scratch/tng204/thesis/bachelor_thesis/stable_char_transformer.py", line 1094, in main
Traceback (most recent call last):
  File "/var/scratch/tng204/thesis/bachelor_thesis/stable_char_transformer.py", line 1196, in <module>
    train_batches, start_batch = create_batches(train_data, local_batch_size, seq_length)
  File "/var/scratch/tng204/thesis/bachelor_thesis/stable_char_transformer.py", line 120, in create_batches
    chunk = chunk.view(batch_size, seq_length + 1)
RuntimeError: shape '[2, 1025]' is invalid for input of size 2049
    main()
  File "/var/scratch/tng204/thesis/bachelor_thesis/stable_char_transformer.py", line 1094, in main
    train_batches, start_batch = create_batches(train_data, local_batch_size, seq_length)
  File "/var/scratch/tng204/thesis/bachelor_thesis/stable_char_transformer.py", line 120, in create_batches
    chunk = chunk.view(batch_size, seq_length + 1)
RuntimeError: shape '[2, 1025]' is invalid for input of size 2049
Traceback (most recent call last):
  File "/var/scratch/tng204/thesis/bachelor_thesis/stable_char_transformer.py", line 1196, in <module>
    main()
  File "/var/scratch/tng204/thesis/bachelor_thesis/stable_char_transformer.py", line 1094, in main
    train_batches, start_batch = create_batches(train_data, local_batch_size, seq_length)
  File "/var/scratch/tng204/thesis/bachelor_thesis/stable_char_transformer.py", line 120, in create_batches
    chunk = chunk.view(batch_size, seq_length + 1)
RuntimeError: shape '[2, 1025]' is invalid for input of size 2049
Traceback (most recent call last):
  File "/var/scratch/tng204/thesis/bachelor_thesis/stable_char_transformer.py", line 1196, in <module>
    main()
  File "/var/scratch/tng204/thesis/bachelor_thesis/stable_char_transformer.py", line 1094, in main
    train_batches, start_batch = create_batches(train_data, local_batch_size, seq_length)
  File "/var/scratch/tng204/thesis/bachelor_thesis/stable_char_transformer.py", line 120, in create_batches
    chunk = chunk.view(batch_size, seq_length + 1)
RuntimeError: shape '[2, 1025]' is invalid for input of size 2049
Traceback (most recent call last):
  File "/var/scratch/tng204/thesis/bachelor_thesis/stable_char_transformer.py", line 1196, in <module>
    main()
  File "/var/scratch/tng204/thesis/bachelor_thesis/stable_char_transformer.py", line 1094, in main
    train_batches, start_batch = create_batches(train_data, local_batch_size, seq_length)
  File "/var/scratch/tng204/thesis/bachelor_thesis/stable_char_transformer.py", line 120, in create_batches
    chunk = chunk.view(batch_size, seq_length + 1)
RuntimeError: shape '[2, 1025]' is invalid for input of size 2049
Traceback (most recent call last):
  File "/var/scratch/tng204/thesis/bachelor_thesis/stable_char_transformer.py", line 1196, in <module>
    main()
  File "/var/scratch/tng204/thesis/bachelor_thesis/stable_char_transformer.py", line 1094, in main
    train_batches, start_batch = create_batches(train_data, local_batch_size, seq_length)
  File "/var/scratch/tng204/thesis/bachelor_thesis/stable_char_transformer.py", line 120, in create_batches
    chunk = chunk.view(batch_size, seq_length + 1)
RuntimeError: shape '[2, 1025]' is invalid for input of size 2049
Traceback (most recent call last):
  File "/var/scratch/tng204/thesis/bachelor_thesis/stable_char_transformer.py", line 1196, in <module>
    main()
  File "/var/scratch/tng204/thesis/bachelor_thesis/stable_char_transformer.py", line 1094, in main
    train_batches, start_batch = create_batches(train_data, local_batch_size, seq_length)
  File "/var/scratch/tng204/thesis/bachelor_thesis/stable_char_transformer.py", line 120, in create_batches
    chunk = chunk.view(batch_size, seq_length + 1)
RuntimeError: shape '[2, 1025]' is invalid for input of size 2049
Traceback (most recent call last):
  File "/var/scratch/tng204/thesis/bachelor_thesis/stable_char_transformer.py", line 1196, in <module>
    main()
  File "/var/scratch/tng204/thesis/bachelor_thesis/stable_char_transformer.py", line 1094, in main
    train_batches, start_batch = create_batches(train_data, local_batch_size, seq_length)
  File "/var/scratch/tng204/thesis/bachelor_thesis/stable_char_transformer.py", line 120, in create_batches
    chunk = chunk.view(batch_size, seq_length + 1)
RuntimeError: shape '[2, 1025]' is invalid for input of size 2049
Traceback (most recent call last):
  File "/var/scratch/tng204/thesis/bachelor_thesis/stable_char_transformer.py", line 1196, in <module>
    main()
  File "/var/scratch/tng204/thesis/bachelor_thesis/stable_char_transformer.py", line 1094, in main
    train_batches, start_batch = create_batches(train_data, local_batch_size, seq_length)
  File "/var/scratch/tng204/thesis/bachelor_thesis/stable_char_transformer.py", line 120, in create_batches
    chunk = chunk.view(batch_size, seq_length + 1)
RuntimeError: shape '[2, 1025]' is invalid for input of size 2049
Traceback (most recent call last):
  File "/var/scratch/tng204/thesis/bachelor_thesis/stable_char_transformer.py", line 1196, in <module>
    main()
  File "/var/scratch/tng204/thesis/bachelor_thesis/stable_char_transformer.py", line 1094, in main
    train_batches, start_batch = create_batches(train_data, local_batch_size, seq_length)
  File "/var/scratch/tng204/thesis/bachelor_thesis/stable_char_transformer.py", line 120, in create_batches
    chunk = chunk.view(batch_size, seq_length + 1)
RuntimeError: shape '[2, 1025]' is invalid for input of size 2049
Traceback (most recent call last):
  File "/var/scratch/tng204/thesis/bachelor_thesis/stable_char_transformer.py", line 1196, in <module>
    main()
  File "/var/scratch/tng204/thesis/bachelor_thesis/stable_char_transformer.py", line 1094, in main
    train_batches, start_batch = create_batches(train_data, local_batch_size, seq_length)
  File "/var/scratch/tng204/thesis/bachelor_thesis/stable_char_transformer.py", line 120, in create_batches
    chunk = chunk.view(batch_size, seq_length + 1)
RuntimeError: shape '[2, 1025]' is invalid for input of size 2049
ERROR:torch.distributed.elastic.multiprocessing.api:failed (exitcode: 1) local_rank: 0 (pid: 837706) of binary: /var/scratch/tng204/anaconda3/envs/mltrain/bin/python3.10
Traceback (most recent call last):
  File "/var/scratch/tng204/thesis/bachelor_thesis/stable_char_transformer.py", line 1196, in <module>
    main()
  File "/var/scratch/tng204/thesis/bachelor_thesis/stable_char_transformer.py", line 1094, in main
    train_batches, start_batch = create_batches(train_data, local_batch_size, seq_length)
  File "/var/scratch/tng204/thesis/bachelor_thesis/stable_char_transformer.py", line 120, in create_batches
    chunk = chunk.view(batch_size, seq_length + 1)
RuntimeError: shape '[2, 1025]' is invalid for input of size 2049
Traceback (most recent call last):
  File "/var/scratch/tng204/thesis/bachelor_thesis/stable_char_transformer.py", line 1196, in <module>
    main()
  File "/var/scratch/tng204/thesis/bachelor_thesis/stable_char_transformer.py", line 1094, in main
    train_batches, start_batch = create_batches(train_data, local_batch_size, seq_length)
  File "/var/scratch/tng204/thesis/bachelor_thesis/stable_char_transformer.py", line 120, in create_batches
    chunk = chunk.view(batch_size, seq_length + 1)
RuntimeError: shape '[2, 1025]' is invalid for input of size 2049
Traceback (most recent call last):
  File "/var/scratch/tng204/thesis/bachelor_thesis/stable_char_transformer.py", line 1196, in <module>
    main()
  File "/var/scratch/tng204/thesis/bachelor_thesis/stable_char_transformer.py", line 1094, in main
    train_batches, start_batch = create_batches(train_data, local_batch_size, seq_length)
  File "/var/scratch/tng204/thesis/bachelor_thesis/stable_char_transformer.py", line 120, in create_batches
    chunk = chunk.view(batch_size, seq_length + 1)
RuntimeError: shape '[2, 1025]' is invalid for input of size 2049
ERROR:torch.distributed.elastic.multiprocessing.api:failed (exitcode: 1) local_rank: 0 (pid: 3578859) of binary: /var/scratch/tng204/anaconda3/envs/mltrain/bin/python3.10
ERROR:torch.distributed.elastic.multiprocessing.api:failed (exitcode: 1) local_rank: 0 (pid: 782860) of binary: /var/scratch/tng204/anaconda3/envs/mltrain/bin/python3.10
ERROR:torch.distributed.elastic.multiprocessing.api:failed (exitcode: 1) local_rank: 0 (pid: 705068) of binary: /var/scratch/tng204/anaconda3/envs/mltrain/bin/python3.10
ERROR:torch.distributed.elastic.multiprocessing.api:failed (exitcode: 1) local_rank: 0 (pid: 700852) of binary: /var/scratch/tng204/anaconda3/envs/mltrain/bin/python3.10
ERROR:torch.distributed.elastic.multiprocessing.api:failed (exitcode: 1) local_rank: 0 (pid: 685054) of binary: /var/scratch/tng204/anaconda3/envs/mltrain/bin/python3.10
ERROR:torch.distributed.elastic.multiprocessing.api:failed (exitcode: 1) local_rank: 0 (pid: 723752) of binary: /var/scratch/tng204/anaconda3/envs/mltrain/bin/python3.10
ERROR:torch.distributed.elastic.multiprocessing.api:failed (exitcode: 1) local_rank: 0 (pid: 716494) of binary: /var/scratch/tng204/anaconda3/envs/mltrain/bin/python3.10
ERROR:torch.distributed.elastic.multiprocessing.api:failed (exitcode: 1) local_rank: 0 (pid: 685298) of binary: /var/scratch/tng204/anaconda3/envs/mltrain/bin/python3.10
ERROR:torch.distributed.elastic.multiprocessing.api:failed (exitcode: 1) local_rank: 0 (pid: 1006846) of binary: /var/scratch/tng204/anaconda3/envs/mltrain/bin/python3.10
ERROR:torch.distributed.elastic.multiprocessing.api:failed (exitcode: 1) local_rank: 0 (pid: 703557) of binary: /var/scratch/tng204/anaconda3/envs/mltrain/bin/python3.10
ERROR:torch.distributed.elastic.multiprocessing.api:failed (exitcode: 1) local_rank: 0 (pid: 804400) of binary: /var/scratch/tng204/anaconda3/envs/mltrain/bin/python3.10
ERROR:torch.distributed.elastic.multiprocessing.api:failed (exitcode: 1) local_rank: 0 (pid: 672563) of binary: /var/scratch/tng204/anaconda3/envs/mltrain/bin/python3.10
ERROR:torch.distributed.elastic.multiprocessing.api:failed (exitcode: 1) local_rank: 0 (pid: 696315) of binary: /var/scratch/tng204/anaconda3/envs/mltrain/bin/python3.10
ERROR:torch.distributed.elastic.multiprocessing.api:failed (exitcode: 1) local_rank: 0 (pid: 814903) of binary: /var/scratch/tng204/anaconda3/envs/mltrain/bin/python3.10
ERROR:torch.distributed.elastic.multiprocessing.api:failed (exitcode: 1) local_rank: 0 (pid: 702128) of binary: /var/scratch/tng204/anaconda3/envs/mltrain/bin/python3.10
Traceback (most recent call last):
  File "/var/scratch/tng204/thesis/bachelor_thesis/stable_char_transformer.py", line 1196, in <module>
    main()
  File "/var/scratch/tng204/thesis/bachelor_thesis/stable_char_transformer.py", line 1094, in main
    train_batches, start_batch = create_batches(train_data, local_batch_size, seq_length)
  File "/var/scratch/tng204/thesis/bachelor_thesis/stable_char_transformer.py", line 120, in create_batches
    chunk = chunk.view(batch_size, seq_length + 1)
RuntimeError: shape '[2, 1025]' is invalid for input of size 2049
Traceback (most recent call last):
  File "/var/scratch/tng204/thesis/bachelor_thesis/stable_char_transformer.py", line 1196, in <module>
    main()
  File "/var/scratch/tng204/thesis/bachelor_thesis/stable_char_transformer.py", line 1094, in main
    train_batches, start_batch = create_batches(train_data, local_batch_size, seq_length)
  File "/var/scratch/tng204/thesis/bachelor_thesis/stable_char_transformer.py", line 120, in create_batches
    chunk = chunk.view(batch_size, seq_length + 1)
Traceback (most recent call last):
  File "/var/scratch/tng204/thesis/bachelor_thesis/stable_char_transformer.py", line 1196, in <module>
RuntimeError: shape '[2, 1025]' is invalid for input of size 2049
    main()
  File "/var/scratch/tng204/thesis/bachelor_thesis/stable_char_transformer.py", line 1094, in main
    train_batches, start_batch = create_batches(train_data, local_batch_size, seq_length)
  File "/var/scratch/tng204/thesis/bachelor_thesis/stable_char_transformer.py", line 120, in create_batches
    chunk = chunk.view(batch_size, seq_length + 1)
RuntimeError: shape '[2, 1025]' is invalid for input of size 2049
Traceback (most recent call last):
  File "/var/scratch/tng204/thesis/bachelor_thesis/stable_char_transformer.py", line 1196, in <module>
    main()
  File "/var/scratch/tng204/thesis/bachelor_thesis/stable_char_transformer.py", line 1094, in main
    train_batches, start_batch = create_batches(train_data, local_batch_size, seq_length)
  File "/var/scratch/tng204/thesis/bachelor_thesis/stable_char_transformer.py", line 120, in create_batches
    chunk = chunk.view(batch_size, seq_length + 1)
RuntimeError: shape '[2, 1025]' is invalid for input of size 2049
Traceback (most recent call last):
  File "/var/scratch/tng204/thesis/bachelor_thesis/stable_char_transformer.py", line 1196, in <module>
Traceback (most recent call last):
  File "/var/scratch/tng204/thesis/bachelor_thesis/stable_char_transformer.py", line 1196, in <module>
    main()
  File "/var/scratch/tng204/thesis/bachelor_thesis/stable_char_transformer.py", line 1094, in main
    main()
  File "/var/scratch/tng204/thesis/bachelor_thesis/stable_char_transformer.py", line 1094, in main
    train_batches, start_batch = create_batches(train_data, local_batch_size, seq_length)
  File "/var/scratch/tng204/thesis/bachelor_thesis/stable_char_transformer.py", line 120, in create_batches
    train_batches, start_batch = create_batches(train_data, local_batch_size, seq_length)
  File "/var/scratch/tng204/thesis/bachelor_thesis/stable_char_transformer.py", line 120, in create_batches
    chunk = chunk.view(batch_size, seq_length + 1)
RuntimeError: shape '[2, 1025]' is invalid for input of size 2049
    chunk = chunk.view(batch_size, seq_length + 1)
RuntimeError: shape '[2, 1025]' is invalid for input of size 2049
Traceback (most recent call last):
  File "/var/scratch/tng204/thesis/bachelor_thesis/stable_char_transformer.py", line 1196, in <module>
    main()
  File "/var/scratch/tng204/thesis/bachelor_thesis/stable_char_transformer.py", line 1094, in main
    train_batches, start_batch = create_batches(train_data, local_batch_size, seq_length)
  File "/var/scratch/tng204/thesis/bachelor_thesis/stable_char_transformer.py", line 120, in create_batches
    chunk = chunk.view(batch_size, seq_length + 1)
RuntimeError: shape '[2, 1025]' is invalid for input of size 2049
Traceback (most recent call last):
  File "/var/scratch/tng204/thesis/bachelor_thesis/stable_char_transformer.py", line 1196, in <module>
    main()
  File "/var/scratch/tng204/thesis/bachelor_thesis/stable_char_transformer.py", line 1094, in main
    train_batches, start_batch = create_batches(train_data, local_batch_size, seq_length)
  File "/var/scratch/tng204/thesis/bachelor_thesis/stable_char_transformer.py", line 120, in create_batches
    chunk = chunk.view(batch_size, seq_length + 1)
RuntimeError: shape '[2, 1025]' is invalid for input of size 2049
Traceback (most recent call last):
  File "/var/scratch/tng204/thesis/bachelor_thesis/stable_char_transformer.py", line 1196, in <module>
    main()
  File "/var/scratch/tng204/thesis/bachelor_thesis/stable_char_transformer.py", line 1094, in main
    train_batches, start_batch = create_batches(train_data, local_batch_size, seq_length)
  File "/var/scratch/tng204/thesis/bachelor_thesis/stable_char_transformer.py", line 120, in create_batches
    chunk = chunk.view(batch_size, seq_length + 1)
RuntimeError: shape '[2, 1025]' is invalid for input of size 2049
Traceback (most recent call last):
  File "/var/scratch/tng204/thesis/bachelor_thesis/stable_char_transformer.py", line 1196, in <module>
    main()
  File "/var/scratch/tng204/thesis/bachelor_thesis/stable_char_transformer.py", line 1094, in main
    train_batches, start_batch = create_batches(train_data, local_batch_size, seq_length)
  File "/var/scratch/tng204/thesis/bachelor_thesis/stable_char_transformer.py", line 120, in create_batches
    chunk = chunk.view(batch_size, seq_length + 1)
RuntimeError: shape '[2, 1025]' is invalid for input of size 2049
Traceback (most recent call last):
  File "/var/scratch/tng204/thesis/bachelor_thesis/stable_char_transformer.py", line 1196, in <module>
    main()
  File "/var/scratch/tng204/thesis/bachelor_thesis/stable_char_transformer.py", line 1094, in main
Traceback (most recent call last):
  File "/var/scratch/tng204/thesis/bachelor_thesis/stable_char_transformer.py", line 1196, in <module>
    train_batches, start_batch = create_batches(train_data, local_batch_size, seq_length)
  File "/var/scratch/tng204/thesis/bachelor_thesis/stable_char_transformer.py", line 120, in create_batches
    chunk = chunk.view(batch_size, seq_length + 1)
RuntimeError: shape '[2, 1025]' is invalid for input of size 2049
    main()
  File "/var/scratch/tng204/thesis/bachelor_thesis/stable_char_transformer.py", line 1094, in main
    train_batches, start_batch = create_batches(train_data, local_batch_size, seq_length)
  File "/var/scratch/tng204/thesis/bachelor_thesis/stable_char_transformer.py", line 120, in create_batches
    chunk = chunk.view(batch_size, seq_length + 1)
RuntimeError: shape '[2, 1025]' is invalid for input of size 2049
Traceback (most recent call last):
  File "/var/scratch/tng204/thesis/bachelor_thesis/stable_char_transformer.py", line 1196, in <module>
    main()
  File "/var/scratch/tng204/thesis/bachelor_thesis/stable_char_transformer.py", line 1094, in main
    train_batches, start_batch = create_batches(train_data, local_batch_size, seq_length)
  File "/var/scratch/tng204/thesis/bachelor_thesis/stable_char_transformer.py", line 120, in create_batches
    chunk = chunk.view(batch_size, seq_length + 1)
RuntimeError: shape '[2, 1025]' is invalid for input of size 2049
ERROR:torch.distributed.elastic.multiprocessing.api:failed (exitcode: 1) local_rank: 0 (pid: 837725) of binary: /var/scratch/tng204/anaconda3/envs/mltrain/bin/python3.10
Traceback (most recent call last):
  File "/var/scratch/tng204/thesis/bachelor_thesis/stable_char_transformer.py", line 1196, in <module>
    main()
  File "/var/scratch/tng204/thesis/bachelor_thesis/stable_char_transformer.py", line 1094, in main
    train_batches, start_batch = create_batches(train_data, local_batch_size, seq_length)
  File "/var/scratch/tng204/thesis/bachelor_thesis/stable_char_transformer.py", line 120, in create_batches
    chunk = chunk.view(batch_size, seq_length + 1)
RuntimeError: shape '[2, 1025]' is invalid for input of size 2049
Traceback (most recent call last):
  File "/var/scratch/tng204/thesis/bachelor_thesis/stable_char_transformer.py", line 1196, in <module>
    main()
  File "/var/scratch/tng204/thesis/bachelor_thesis/stable_char_transformer.py", line 1094, in main
    train_batches, start_batch = create_batches(train_data, local_batch_size, seq_length)
  File "/var/scratch/tng204/thesis/bachelor_thesis/stable_char_transformer.py", line 120, in create_batches
    chunk = chunk.view(batch_size, seq_length + 1)
RuntimeError: shape '[2, 1025]' is invalid for input of size 2049
Traceback (most recent call last):
  File "/var/scratch/tng204/thesis/bachelor_thesis/stable_char_transformer.py", line 1196, in <module>
    main()
  File "/var/scratch/tng204/thesis/bachelor_thesis/stable_char_transformer.py", line 1094, in main
    train_batches, start_batch = create_batches(train_data, local_batch_size, seq_length)
  File "/var/scratch/tng204/thesis/bachelor_thesis/stable_char_transformer.py", line 120, in create_batches
    chunk = chunk.view(batch_size, seq_length + 1)
RuntimeError: shape '[2, 1025]' is invalid for input of size 2049
ERROR:torch.distributed.elastic.multiprocessing.api:failed (exitcode: 1) local_rank: 0 (pid: 672579) of binary: /var/scratch/tng204/anaconda3/envs/mltrain/bin/python3.10
ERROR:torch.distributed.elastic.multiprocessing.api:failed (exitcode: 1) local_rank: 0 (pid: 1006871) of binary: /var/scratch/tng204/anaconda3/envs/mltrain/bin/python3.10
ERROR:torch.distributed.elastic.multiprocessing.api:failed (exitcode: 1) local_rank: 0 (pid: 3578875) of binary: /var/scratch/tng204/anaconda3/envs/mltrain/bin/python3.10
ERROR:torch.distributed.elastic.multiprocessing.api:failed (exitcode: 1) local_rank: 0 (pid: 703583) of binary: /var/scratch/tng204/anaconda3/envs/mltrain/bin/python3.10
ERROR:torch.distributed.elastic.multiprocessing.api:failed (exitcode: 1) local_rank: 0 (pid: 782876) of binary: /var/scratch/tng204/anaconda3/envs/mltrain/bin/python3.10
ERROR:torch.distributed.elastic.multiprocessing.api:failed (exitcode: 1) local_rank: 0 (pid: 716510) of binary: /var/scratch/tng204/anaconda3/envs/mltrain/bin/python3.10
ERROR:torch.distributed.elastic.multiprocessing.api:failed (exitcode: 1) local_rank: 0 (pid: 814919) of binary: /var/scratch/tng204/anaconda3/envs/mltrain/bin/python3.10
ERROR:torch.distributed.elastic.multiprocessing.api:failed (exitcode: 1) local_rank: 0 (pid: 696331) of binary: /var/scratch/tng204/anaconda3/envs/mltrain/bin/python3.10
ERROR:torch.distributed.elastic.multiprocessing.api:failed (exitcode: 1) local_rank: 0 (pid: 723768) of binary: /var/scratch/tng204/anaconda3/envs/mltrain/bin/python3.10
ERROR:torch.distributed.elastic.multiprocessing.api:failed (exitcode: 1) local_rank: 0 (pid: 700877) of binary: /var/scratch/tng204/anaconda3/envs/mltrain/bin/python3.10
ERROR:torch.distributed.elastic.multiprocessing.api:failed (exitcode: 1) local_rank: 0 (pid: 705084) of binary: /var/scratch/tng204/anaconda3/envs/mltrain/bin/python3.10
ERROR:torch.distributed.elastic.multiprocessing.api:failed (exitcode: 1) local_rank: 0 (pid: 702144) of binary: /var/scratch/tng204/anaconda3/envs/mltrain/bin/python3.10
ERROR:torch.distributed.elastic.multiprocessing.api:failed (exitcode: 1) local_rank: 0 (pid: 685070) of binary: /var/scratch/tng204/anaconda3/envs/mltrain/bin/python3.10
ERROR:torch.distributed.elastic.multiprocessing.api:failed (exitcode: 1) local_rank: 0 (pid: 804416) of binary: /var/scratch/tng204/anaconda3/envs/mltrain/bin/python3.10
ERROR:torch.distributed.elastic.multiprocessing.api:failed (exitcode: 1) local_rank: 0 (pid: 685314) of binary: /var/scratch/tng204/anaconda3/envs/mltrain/bin/python3.10
Traceback (most recent call last):
  File "/var/scratch/tng204/thesis/bachelor_thesis/stable_char_transformer.py", line 1196, in <module>
    main()
  File "/var/scratch/tng204/thesis/bachelor_thesis/stable_char_transformer.py", line 1094, in main
    train_batches, start_batch = create_batches(train_data, local_batch_size, seq_length)
  File "/var/scratch/tng204/thesis/bachelor_thesis/stable_char_transformer.py", line 120, in create_batches
    chunk = chunk.view(batch_size, seq_length + 1)
RuntimeError: shape '[2, 1025]' is invalid for input of size 2049
Traceback (most recent call last):
  File "/var/scratch/tng204/thesis/bachelor_thesis/stable_char_transformer.py", line 1196, in <module>
    main()
  File "/var/scratch/tng204/thesis/bachelor_thesis/stable_char_transformer.py", line 1094, in main
    train_batches, start_batch = create_batches(train_data, local_batch_size, seq_length)
  File "/var/scratch/tng204/thesis/bachelor_thesis/stable_char_transformer.py", line 120, in create_batches
    chunk = chunk.view(batch_size, seq_length + 1)
RuntimeError: shape '[2, 1025]' is invalid for input of size 2049
Traceback (most recent call last):
  File "/var/scratch/tng204/thesis/bachelor_thesis/stable_char_transformer.py", line 1196, in <module>
    main()
  File "/var/scratch/tng204/thesis/bachelor_thesis/stable_char_transformer.py", line 1094, in main
    train_batches, start_batch = create_batches(train_data, local_batch_size, seq_length)
  File "/var/scratch/tng204/thesis/bachelor_thesis/stable_char_transformer.py", line 120, in create_batches
    chunk = chunk.view(batch_size, seq_length + 1)
RuntimeError: shape '[2, 1025]' is invalid for input of size 2049
Traceback (most recent call last):
  File "/var/scratch/tng204/thesis/bachelor_thesis/stable_char_transformer.py", line 1196, in <module>
    main()
  File "/var/scratch/tng204/thesis/bachelor_thesis/stable_char_transformer.py", line 1094, in main
    train_batches, start_batch = create_batches(train_data, local_batch_size, seq_length)
  File "/var/scratch/tng204/thesis/bachelor_thesis/stable_char_transformer.py", line 120, in create_batches
    chunk = chunk.view(batch_size, seq_length + 1)
RuntimeError: shape '[2, 1025]' is invalid for input of size 2049
Traceback (most recent call last):
  File "/var/scratch/tng204/thesis/bachelor_thesis/stable_char_transformer.py", line 1196, in <module>
    main()
  File "/var/scratch/tng204/thesis/bachelor_thesis/stable_char_transformer.py", line 1094, in main
    train_batches, start_batch = create_batches(train_data, local_batch_size, seq_length)
  File "/var/scratch/tng204/thesis/bachelor_thesis/stable_char_transformer.py", line 120, in create_batches
    chunk = chunk.view(batch_size, seq_length + 1)
RuntimeError: shape '[2, 1025]' is invalid for input of size 2049
Traceback (most recent call last):
  File "/var/scratch/tng204/thesis/bachelor_thesis/stable_char_transformer.py", line 1196, in <module>
Traceback (most recent call last):
  File "/var/scratch/tng204/thesis/bachelor_thesis/stable_char_transformer.py", line 1196, in <module>
    main()
  File "/var/scratch/tng204/thesis/bachelor_thesis/stable_char_transformer.py", line 1094, in main
    main()
  File "/var/scratch/tng204/thesis/bachelor_thesis/stable_char_transformer.py", line 1094, in main
    train_batches, start_batch = create_batches(train_data, local_batch_size, seq_length)
  File "/var/scratch/tng204/thesis/bachelor_thesis/stable_char_transformer.py", line 120, in create_batches
    train_batches, start_batch = create_batches(train_data, local_batch_size, seq_length)
  File "/var/scratch/tng204/thesis/bachelor_thesis/stable_char_transformer.py", line 120, in create_batches
    chunk = chunk.view(batch_size, seq_length + 1)
    chunk = chunk.view(batch_size, seq_length + 1)
RuntimeError: shape '[2, 1025]' is invalid for input of size 2049
RuntimeError: shape '[2, 1025]' is invalid for input of size 2049
Traceback (most recent call last):
  File "/var/scratch/tng204/thesis/bachelor_thesis/stable_char_transformer.py", line 1196, in <module>
    main()
  File "/var/scratch/tng204/thesis/bachelor_thesis/stable_char_transformer.py", line 1094, in main
    train_batches, start_batch = create_batches(train_data, local_batch_size, seq_length)
  File "/var/scratch/tng204/thesis/bachelor_thesis/stable_char_transformer.py", line 120, in create_batches
    chunk = chunk.view(batch_size, seq_length + 1)
RuntimeError: shape '[2, 1025]' is invalid for input of size 2049
Traceback (most recent call last):
  File "/var/scratch/tng204/thesis/bachelor_thesis/stable_char_transformer.py", line 1196, in <module>
    main()
  File "/var/scratch/tng204/thesis/bachelor_thesis/stable_char_transformer.py", line 1094, in main
    train_batches, start_batch = create_batches(train_data, local_batch_size, seq_length)
  File "/var/scratch/tng204/thesis/bachelor_thesis/stable_char_transformer.py", line 120, in create_batches
    chunk = chunk.view(batch_size, seq_length + 1)
RuntimeError: shape '[2, 1025]' is invalid for input of size 2049
Traceback (most recent call last):
  File "/var/scratch/tng204/thesis/bachelor_thesis/stable_char_transformer.py", line 1196, in <module>
    main()
  File "/var/scratch/tng204/thesis/bachelor_thesis/stable_char_transformer.py", line 1094, in main
    train_batches, start_batch = create_batches(train_data, local_batch_size, seq_length)
  File "/var/scratch/tng204/thesis/bachelor_thesis/stable_char_transformer.py", line 120, in create_batches
    chunk = chunk.view(batch_size, seq_length + 1)
RuntimeError: shape '[2, 1025]' is invalid for input of size 2049
Traceback (most recent call last):
  File "/var/scratch/tng204/thesis/bachelor_thesis/stable_char_transformer.py", line 1196, in <module>
    main()
  File "/var/scratch/tng204/thesis/bachelor_thesis/stable_char_transformer.py", line 1094, in main
    train_batches, start_batch = create_batches(train_data, local_batch_size, seq_length)
  File "/var/scratch/tng204/thesis/bachelor_thesis/stable_char_transformer.py", line 120, in create_batches
    chunk = chunk.view(batch_size, seq_length + 1)
RuntimeError: shape '[2, 1025]' is invalid for input of size 2049
Traceback (most recent call last):
  File "/var/scratch/tng204/thesis/bachelor_thesis/stable_char_transformer.py", line 1196, in <module>
    main()
  File "/var/scratch/tng204/thesis/bachelor_thesis/stable_char_transformer.py", line 1094, in main
    train_batches, start_batch = create_batches(train_data, local_batch_size, seq_length)
  File "/var/scratch/tng204/thesis/bachelor_thesis/stable_char_transformer.py", line 120, in create_batches
    chunk = chunk.view(batch_size, seq_length + 1)
RuntimeError: shape '[2, 1025]' is invalid for input of size 2049
Traceback (most recent call last):
  File "/var/scratch/tng204/thesis/bachelor_thesis/stable_char_transformer.py", line 1196, in <module>
    main()
  File "/var/scratch/tng204/thesis/bachelor_thesis/stable_char_transformer.py", line 1094, in main
    train_batches, start_batch = create_batches(train_data, local_batch_size, seq_length)
  File "/var/scratch/tng204/thesis/bachelor_thesis/stable_char_transformer.py", line 120, in create_batches
    chunk = chunk.view(batch_size, seq_length + 1)
RuntimeError: shape '[2, 1025]' is invalid for input of size 2049
ERROR:torch.distributed.elastic.multiprocessing.api:failed (exitcode: 1) local_rank: 0 (pid: 837743) of binary: /var/scratch/tng204/anaconda3/envs/mltrain/bin/python3.10
ERROR:torch.distributed.elastic.multiprocessing.api:failed (exitcode: 1) local_rank: 0 (pid: 685086) of binary: /var/scratch/tng204/anaconda3/envs/mltrain/bin/python3.10
Traceback (most recent call last):
  File "/var/scratch/tng204/thesis/bachelor_thesis/stable_char_transformer.py", line 1196, in <module>
    main()
  File "/var/scratch/tng204/thesis/bachelor_thesis/stable_char_transformer.py", line 1094, in main
    train_batches, start_batch = create_batches(train_data, local_batch_size, seq_length)
  File "/var/scratch/tng204/thesis/bachelor_thesis/stable_char_transformer.py", line 120, in create_batches
    chunk = chunk.view(batch_size, seq_length + 1)
RuntimeError: shape '[2, 1025]' is invalid for input of size 2049
Traceback (most recent call last):
  File "/var/scratch/tng204/thesis/bachelor_thesis/stable_char_transformer.py", line 1196, in <module>
    main()
  File "/var/scratch/tng204/thesis/bachelor_thesis/stable_char_transformer.py", line 1094, in main
    train_batches, start_batch = create_batches(train_data, local_batch_size, seq_length)
  File "/var/scratch/tng204/thesis/bachelor_thesis/stable_char_transformer.py", line 120, in create_batches
    chunk = chunk.view(batch_size, seq_length + 1)
RuntimeError: shape '[2, 1025]' is invalid for input of size 2049
Traceback (most recent call last):
  File "/var/scratch/tng204/thesis/bachelor_thesis/stable_char_transformer.py", line 1196, in <module>
    main()
  File "/var/scratch/tng204/thesis/bachelor_thesis/stable_char_transformer.py", line 1094, in main
    train_batches, start_batch = create_batches(train_data, local_batch_size, seq_length)
  File "/var/scratch/tng204/thesis/bachelor_thesis/stable_char_transformer.py", line 120, in create_batches
    chunk = chunk.view(batch_size, seq_length + 1)
RuntimeError: shape '[2, 1025]' is invalid for input of size 2049
ERROR:torch.distributed.elastic.multiprocessing.api:failed (exitcode: 1) local_rank: 0 (pid: 702160) of binary: /var/scratch/tng204/anaconda3/envs/mltrain/bin/python3.10
ERROR:torch.distributed.elastic.multiprocessing.api:failed (exitcode: 1) local_rank: 0 (pid: 3578891) of binary: /var/scratch/tng204/anaconda3/envs/mltrain/bin/python3.10
ERROR:torch.distributed.elastic.multiprocessing.api:failed (exitcode: 1) local_rank: 0 (pid: 782892) of binary: /var/scratch/tng204/anaconda3/envs/mltrain/bin/python3.10
ERROR:torch.distributed.elastic.multiprocessing.api:failed (exitcode: 1) local_rank: 0 (pid: 685330) of binary: /var/scratch/tng204/anaconda3/envs/mltrain/bin/python3.10
ERROR:torch.distributed.elastic.multiprocessing.api:failed (exitcode: 1) local_rank: 0 (pid: 696347) of binary: /var/scratch/tng204/anaconda3/envs/mltrain/bin/python3.10
ERROR:torch.distributed.elastic.multiprocessing.api:failed (exitcode: 1) local_rank: 0 (pid: 703599) of binary: /var/scratch/tng204/anaconda3/envs/mltrain/bin/python3.10
ERROR:torch.distributed.elastic.multiprocessing.api:failed (exitcode: 1) local_rank: 0 (pid: 716526) of binary: /var/scratch/tng204/anaconda3/envs/mltrain/bin/python3.10
ERROR:torch.distributed.elastic.multiprocessing.api:failed (exitcode: 1) local_rank: 0 (pid: 705100) of binary: /var/scratch/tng204/anaconda3/envs/mltrain/bin/python3.10
ERROR:torch.distributed.elastic.multiprocessing.api:failed (exitcode: 1) local_rank: 0 (pid: 672595) of binary: /var/scratch/tng204/anaconda3/envs/mltrain/bin/python3.10
ERROR:torch.distributed.elastic.multiprocessing.api:failed (exitcode: 1) local_rank: 0 (pid: 814935) of binary: /var/scratch/tng204/anaconda3/envs/mltrain/bin/python3.10
ERROR:torch.distributed.elastic.multiprocessing.api:failed (exitcode: 1) local_rank: 0 (pid: 1006887) of binary: /var/scratch/tng204/anaconda3/envs/mltrain/bin/python3.10
ERROR:torch.distributed.elastic.multiprocessing.api:failed (exitcode: 1) local_rank: 0 (pid: 804432) of binary: /var/scratch/tng204/anaconda3/envs/mltrain/bin/python3.10
ERROR:torch.distributed.elastic.multiprocessing.api:failed (exitcode: 1) local_rank: 0 (pid: 723784) of binary: /var/scratch/tng204/anaconda3/envs/mltrain/bin/python3.10
ERROR:torch.distributed.elastic.multiprocessing.api:failed (exitcode: 1) local_rank: 0 (pid: 700900) of binary: /var/scratch/tng204/anaconda3/envs/mltrain/bin/python3.10
Traceback (most recent call last):
  File "/var/scratch/tng204/thesis/bachelor_thesis/stable_char_transformer.py", line 1196, in <module>
    main()
  File "/var/scratch/tng204/thesis/bachelor_thesis/stable_char_transformer.py", line 1094, in main
    train_batches, start_batch = create_batches(train_data, local_batch_size, seq_length)
  File "/var/scratch/tng204/thesis/bachelor_thesis/stable_char_transformer.py", line 120, in create_batches
    chunk = chunk.view(batch_size, seq_length + 1)
RuntimeError: shape '[2, 1025]' is invalid for input of size 2049
Traceback (most recent call last):
  File "/var/scratch/tng204/thesis/bachelor_thesis/stable_char_transformer.py", line 1196, in <module>
    main()
  File "/var/scratch/tng204/thesis/bachelor_thesis/stable_char_transformer.py", line 1094, in main
    train_batches, start_batch = create_batches(train_data, local_batch_size, seq_length)
  File "/var/scratch/tng204/thesis/bachelor_thesis/stable_char_transformer.py", line 120, in create_batches
    chunk = chunk.view(batch_size, seq_length + 1)
RuntimeError: shape '[2, 1025]' is invalid for input of size 2049
Traceback (most recent call last):
  File "/var/scratch/tng204/thesis/bachelor_thesis/stable_char_transformer.py", line 1196, in <module>
    main()
  File "/var/scratch/tng204/thesis/bachelor_thesis/stable_char_transformer.py", line 1094, in main
    train_batches, start_batch = create_batches(train_data, local_batch_size, seq_length)
  File "/var/scratch/tng204/thesis/bachelor_thesis/stable_char_transformer.py", line 120, in create_batches
    chunk = chunk.view(batch_size, seq_length + 1)
RuntimeError: shape '[2, 1025]' is invalid for input of size 2049
Traceback (most recent call last):
  File "/var/scratch/tng204/thesis/bachelor_thesis/stable_char_transformer.py", line 1196, in <module>
Traceback (most recent call last):
  File "/var/scratch/tng204/thesis/bachelor_thesis/stable_char_transformer.py", line 1196, in <module>
    main()
  File "/var/scratch/tng204/thesis/bachelor_thesis/stable_char_transformer.py", line 1094, in main
    main()
  File "/var/scratch/tng204/thesis/bachelor_thesis/stable_char_transformer.py", line 1094, in main
    train_batches, start_batch = create_batches(train_data, local_batch_size, seq_length)
  File "/var/scratch/tng204/thesis/bachelor_thesis/stable_char_transformer.py", line 120, in create_batches
    train_batches, start_batch = create_batches(train_data, local_batch_size, seq_length)
  File "/var/scratch/tng204/thesis/bachelor_thesis/stable_char_transformer.py", line 120, in create_batches
    chunk = chunk.view(batch_size, seq_length + 1)
RuntimeError: shape '[2, 1025]' is invalid for input of size 2049
    chunk = chunk.view(batch_size, seq_length + 1)
RuntimeError: shape '[2, 1025]' is invalid for input of size 2049
Traceback (most recent call last):
  File "/var/scratch/tng204/thesis/bachelor_thesis/stable_char_transformer.py", line 1196, in <module>
    main()
  File "/var/scratch/tng204/thesis/bachelor_thesis/stable_char_transformer.py", line 1094, in main
    train_batches, start_batch = create_batches(train_data, local_batch_size, seq_length)
  File "/var/scratch/tng204/thesis/bachelor_thesis/stable_char_transformer.py", line 120, in create_batches
    chunk = chunk.view(batch_size, seq_length + 1)
RuntimeError: shape '[2, 1025]' is invalid for input of size 2049
Traceback (most recent call last):
  File "/var/scratch/tng204/thesis/bachelor_thesis/stable_char_transformer.py", line 1196, in <module>
    main()
  File "/var/scratch/tng204/thesis/bachelor_thesis/stable_char_transformer.py", line 1094, in main
    train_batches, start_batch = create_batches(train_data, local_batch_size, seq_length)
  File "/var/scratch/tng204/thesis/bachelor_thesis/stable_char_transformer.py", line 120, in create_batches
    chunk = chunk.view(batch_size, seq_length + 1)
RuntimeError: shape '[2, 1025]' is invalid for input of size 2049
Traceback (most recent call last):
  File "/var/scratch/tng204/thesis/bachelor_thesis/stable_char_transformer.py", line 1196, in <module>
    main()
  File "/var/scratch/tng204/thesis/bachelor_thesis/stable_char_transformer.py", line 1094, in main
    train_batches, start_batch = create_batches(train_data, local_batch_size, seq_length)
  File "/var/scratch/tng204/thesis/bachelor_thesis/stable_char_transformer.py", line 120, in create_batches
    chunk = chunk.view(batch_size, seq_length + 1)
RuntimeError: shape '[2, 1025]' is invalid for input of size 2049
Traceback (most recent call last):
  File "/var/scratch/tng204/thesis/bachelor_thesis/stable_char_transformer.py", line 1196, in <module>
    main()
  File "/var/scratch/tng204/thesis/bachelor_thesis/stable_char_transformer.py", line 1094, in main
    train_batches, start_batch = create_batches(train_data, local_batch_size, seq_length)
  File "/var/scratch/tng204/thesis/bachelor_thesis/stable_char_transformer.py", line 120, in create_batches
    chunk = chunk.view(batch_size, seq_length + 1)
RuntimeError: shape '[2, 1025]' is invalid for input of size 2049
Traceback (most recent call last):
  File "/var/scratch/tng204/thesis/bachelor_thesis/stable_char_transformer.py", line 1196, in <module>
    main()
  File "/var/scratch/tng204/thesis/bachelor_thesis/stable_char_transformer.py", line 1094, in main
    train_batches, start_batch = create_batches(train_data, local_batch_size, seq_length)
  File "/var/scratch/tng204/thesis/bachelor_thesis/stable_char_transformer.py", line 120, in create_batches
    chunk = chunk.view(batch_size, seq_length + 1)
RuntimeError: shape '[2, 1025]' is invalid for input of size 2049
Traceback (most recent call last):
  File "/var/scratch/tng204/thesis/bachelor_thesis/stable_char_transformer.py", line 1196, in <module>
    main()
  File "/var/scratch/tng204/thesis/bachelor_thesis/stable_char_transformer.py", line 1094, in main
    train_batches, start_batch = create_batches(train_data, local_batch_size, seq_length)
  File "/var/scratch/tng204/thesis/bachelor_thesis/stable_char_transformer.py", line 120, in create_batches
    chunk = chunk.view(batch_size, seq_length + 1)
RuntimeError: shape '[2, 1025]' is invalid for input of size 2049
Traceback (most recent call last):
  File "/var/scratch/tng204/thesis/bachelor_thesis/stable_char_transformer.py", line 1196, in <module>
    main()
  File "/var/scratch/tng204/thesis/bachelor_thesis/stable_char_transformer.py", line 1094, in main
    train_batches, start_batch = create_batches(train_data, local_batch_size, seq_length)
  File "/var/scratch/tng204/thesis/bachelor_thesis/stable_char_transformer.py", line 120, in create_batches
    chunk = chunk.view(batch_size, seq_length + 1)
RuntimeError: shape '[2, 1025]' is invalid for input of size 2049
Traceback (most recent call last):
  File "/var/scratch/tng204/thesis/bachelor_thesis/stable_char_transformer.py", line 1196, in <module>
    main()
  File "/var/scratch/tng204/thesis/bachelor_thesis/stable_char_transformer.py", line 1094, in main
    train_batches, start_batch = create_batches(train_data, local_batch_size, seq_length)
  File "/var/scratch/tng204/thesis/bachelor_thesis/stable_char_transformer.py", line 120, in create_batches
    chunk = chunk.view(batch_size, seq_length + 1)
RuntimeError: shape '[2, 1025]' is invalid for input of size 2049
ERROR:torch.distributed.elastic.multiprocessing.api:failed (exitcode: 1) local_rank: 0 (pid: 837761) of binary: /var/scratch/tng204/anaconda3/envs/mltrain/bin/python3.10
Traceback (most recent call last):
  File "/var/scratch/tng204/thesis/bachelor_thesis/stable_char_transformer.py", line 1196, in <module>
    main()
  File "/var/scratch/tng204/thesis/bachelor_thesis/stable_char_transformer.py", line 1094, in main
    train_batches, start_batch = create_batches(train_data, local_batch_size, seq_length)
  File "/var/scratch/tng204/thesis/bachelor_thesis/stable_char_transformer.py", line 120, in create_batches
    chunk = chunk.view(batch_size, seq_length + 1)
RuntimeError: shape '[2, 1025]' is invalid for input of size 2049
Traceback (most recent call last):
  File "/var/scratch/tng204/thesis/bachelor_thesis/stable_char_transformer.py", line 1196, in <module>
    main()
  File "/var/scratch/tng204/thesis/bachelor_thesis/stable_char_transformer.py", line 1094, in main
    train_batches, start_batch = create_batches(train_data, local_batch_size, seq_length)
  File "/var/scratch/tng204/thesis/bachelor_thesis/stable_char_transformer.py", line 120, in create_batches
    chunk = chunk.view(batch_size, seq_length + 1)
RuntimeError: shape '[2, 1025]' is invalid for input of size 2049
Traceback (most recent call last):
  File "/var/scratch/tng204/thesis/bachelor_thesis/stable_char_transformer.py", line 1196, in <module>
    main()
  File "/var/scratch/tng204/thesis/bachelor_thesis/stable_char_transformer.py", line 1094, in main
    train_batches, start_batch = create_batches(train_data, local_batch_size, seq_length)
  File "/var/scratch/tng204/thesis/bachelor_thesis/stable_char_transformer.py", line 120, in create_batches
    chunk = chunk.view(batch_size, seq_length + 1)
RuntimeError: shape '[2, 1025]' is invalid for input of size 2049
ERROR:torch.distributed.elastic.multiprocessing.api:failed (exitcode: 1) local_rank: 0 (pid: 782908) of binary: /var/scratch/tng204/anaconda3/envs/mltrain/bin/python3.10
ERROR:torch.distributed.elastic.multiprocessing.api:failed (exitcode: 1) local_rank: 0 (pid: 700923) of binary: /var/scratch/tng204/anaconda3/envs/mltrain/bin/python3.10
ERROR:torch.distributed.elastic.multiprocessing.api:failed (exitcode: 1) local_rank: 0 (pid: 3578907) of binary: /var/scratch/tng204/anaconda3/envs/mltrain/bin/python3.10
ERROR:torch.distributed.elastic.multiprocessing.api:failed (exitcode: 1) local_rank: 0 (pid: 716542) of binary: /var/scratch/tng204/anaconda3/envs/mltrain/bin/python3.10
ERROR:torch.distributed.elastic.multiprocessing.api:failed (exitcode: 1) local_rank: 0 (pid: 723800) of binary: /var/scratch/tng204/anaconda3/envs/mltrain/bin/python3.10
ERROR:torch.distributed.elastic.multiprocessing.api:failed (exitcode: 1) local_rank: 0 (pid: 672612) of binary: /var/scratch/tng204/anaconda3/envs/mltrain/bin/python3.10
ERROR:torch.distributed.elastic.multiprocessing.api:failed (exitcode: 1) local_rank: 0 (pid: 705116) of binary: /var/scratch/tng204/anaconda3/envs/mltrain/bin/python3.10
ERROR:torch.distributed.elastic.multiprocessing.api:failed (exitcode: 1) local_rank: 0 (pid: 696363) of binary: /var/scratch/tng204/anaconda3/envs/mltrain/bin/python3.10
ERROR:torch.distributed.elastic.multiprocessing.api:failed (exitcode: 1) local_rank: 0 (pid: 814951) of binary: /var/scratch/tng204/anaconda3/envs/mltrain/bin/python3.10
ERROR:torch.distributed.elastic.multiprocessing.api:failed (exitcode: 1) local_rank: 0 (pid: 703615) of binary: /var/scratch/tng204/anaconda3/envs/mltrain/bin/python3.10
ERROR:torch.distributed.elastic.multiprocessing.api:failed (exitcode: 1) local_rank: 0 (pid: 685346) of binary: /var/scratch/tng204/anaconda3/envs/mltrain/bin/python3.10
ERROR:torch.distributed.elastic.multiprocessing.api:failed (exitcode: 1) local_rank: 0 (pid: 1006903) of binary: /var/scratch/tng204/anaconda3/envs/mltrain/bin/python3.10
ERROR:torch.distributed.elastic.multiprocessing.api:failed (exitcode: 1) local_rank: 0 (pid: 702176) of binary: /var/scratch/tng204/anaconda3/envs/mltrain/bin/python3.10
ERROR:torch.distributed.elastic.multiprocessing.api:failed (exitcode: 1) local_rank: 0 (pid: 804448) of binary: /var/scratch/tng204/anaconda3/envs/mltrain/bin/python3.10
ERROR:torch.distributed.elastic.multiprocessing.api:failed (exitcode: 1) local_rank: 0 (pid: 685102) of binary: /var/scratch/tng204/anaconda3/envs/mltrain/bin/python3.10
Traceback (most recent call last):
  File "/var/scratch/tng204/anaconda3/envs/mltrain/bin/torchrun", line 8, in <module>
Traceback (most recent call last):
  File "/var/scratch/tng204/anaconda3/envs/mltrain/bin/torchrun", line 8, in <module>
Traceback (most recent call last):
  File "/var/scratch/tng204/anaconda3/envs/mltrain/bin/torchrun", line 8, in <module>
    sys.exit(main())
  File "/var/scratch/tng204/anaconda3/envs/mltrain/lib/python3.10/site-packages/torch/distributed/elastic/multiprocessing/errors/__init__.py", line 345, in wrapper
    sys.exit(main())
  File "/var/scratch/tng204/anaconda3/envs/mltrain/lib/python3.10/site-packages/torch/distributed/elastic/multiprocessing/errors/__init__.py", line 345, in wrapper
    sys.exit(main())
  File "/var/scratch/tng204/anaconda3/envs/mltrain/lib/python3.10/site-packages/torch/distributed/elastic/multiprocessing/errors/__init__.py", line 345, in wrapper
    return f(*args, **kwargs)
  File "/var/scratch/tng204/anaconda3/envs/mltrain/lib/python3.10/site-packages/torch/distributed/run.py", line 761, in main
    return f(*args, **kwargs)
  File "/var/scratch/tng204/anaconda3/envs/mltrain/lib/python3.10/site-packages/torch/distributed/run.py", line 761, in main
    return f(*args, **kwargs)
  File "/var/scratch/tng204/anaconda3/envs/mltrain/lib/python3.10/site-packages/torch/distributed/run.py", line 761, in main
Traceback (most recent call last):
  File "/var/scratch/tng204/anaconda3/envs/mltrain/bin/torchrun", line 8, in <module>
    run(args)
  File "/var/scratch/tng204/anaconda3/envs/mltrain/lib/python3.10/site-packages/torch/distributed/run.py", line 752, in run
    run(args)
  File "/var/scratch/tng204/anaconda3/envs/mltrain/lib/python3.10/site-packages/torch/distributed/run.py", line 752, in run
    run(args)
  File "/var/scratch/tng204/anaconda3/envs/mltrain/lib/python3.10/site-packages/torch/distributed/run.py", line 752, in run
Traceback (most recent call last):
  File "/var/scratch/tng204/anaconda3/envs/mltrain/bin/torchrun", line 8, in <module>
    sys.exit(main())
  File "/var/scratch/tng204/anaconda3/envs/mltrain/lib/python3.10/site-packages/torch/distributed/elastic/multiprocessing/errors/__init__.py", line 345, in wrapper
Traceback (most recent call last):
  File "/var/scratch/tng204/anaconda3/envs/mltrain/bin/torchrun", line 8, in <module>
    elastic_launch(
  File "/var/scratch/tng204/anaconda3/envs/mltrain/lib/python3.10/site-packages/torch/distributed/launcher/api.py", line 131, in __call__
Traceback (most recent call last):
  File "/var/scratch/tng204/anaconda3/envs/mltrain/bin/torchrun", line 8, in <module>
Traceback (most recent call last):
  File "/var/scratch/tng204/anaconda3/envs/mltrain/bin/torchrun", line 8, in <module>
    elastic_launch(
  File "/var/scratch/tng204/anaconda3/envs/mltrain/lib/python3.10/site-packages/torch/distributed/launcher/api.py", line 131, in __call__
Traceback (most recent call last):
  File "/var/scratch/tng204/anaconda3/envs/mltrain/bin/torchrun", line 8, in <module>
    return launch_agent(self._config, self._entrypoint, list(args))
  File "/var/scratch/tng204/anaconda3/envs/mltrain/lib/python3.10/site-packages/torch/distributed/launcher/api.py", line 245, in launch_agent
    return launch_agent(self._config, self._entrypoint, list(args))
  File "/var/scratch/tng204/anaconda3/envs/mltrain/lib/python3.10/site-packages/torch/distributed/launcher/api.py", line 245, in launch_agent
    sys.exit(main())
  File "/var/scratch/tng204/anaconda3/envs/mltrain/lib/python3.10/site-packages/torch/distributed/elastic/multiprocessing/errors/__init__.py", line 345, in wrapper
Traceback (most recent call last):
  File "/var/scratch/tng204/anaconda3/envs/mltrain/bin/torchrun", line 8, in <module>
    elastic_launch(
  File "/var/scratch/tng204/anaconda3/envs/mltrain/lib/python3.10/site-packages/torch/distributed/launcher/api.py", line 131, in __call__
    sys.exit(main())
  File "/var/scratch/tng204/anaconda3/envs/mltrain/lib/python3.10/site-packages/torch/distributed/elastic/multiprocessing/errors/__init__.py", line 345, in wrapper
    return f(*args, **kwargs)
  File "/var/scratch/tng204/anaconda3/envs/mltrain/lib/python3.10/site-packages/torch/distributed/run.py", line 761, in main
    sys.exit(main())
  File "/var/scratch/tng204/anaconda3/envs/mltrain/lib/python3.10/site-packages/torch/distributed/elastic/multiprocessing/errors/__init__.py", line 345, in wrapper
Traceback (most recent call last):
  File "/var/scratch/tng204/anaconda3/envs/mltrain/bin/torchrun", line 8, in <module>
Traceback (most recent call last):
  File "/var/scratch/tng204/anaconda3/envs/mltrain/bin/torchrun", line 8, in <module>
Traceback (most recent call last):
  File "/var/scratch/tng204/anaconda3/envs/mltrain/bin/torchrun", line 8, in <module>
    raise ChildFailedError(
    sys.exit(main())
  File "/var/scratch/tng204/anaconda3/envs/mltrain/lib/python3.10/site-packages/torch/distributed/elastic/multiprocessing/errors/__init__.py", line 345, in wrapper
    sys.exit(main())
  File "/var/scratch/tng204/anaconda3/envs/mltrain/lib/python3.10/site-packages/torch/distributed/elastic/multiprocessing/errors/__init__.py", line 345, in wrapper
    raise ChildFailedError(
torch.distributed.elastic.multiprocessing.errors.ChildFailedError: 
============================================================
stable_char_transformer.py FAILED
------------------------------------------------------------
Failures:
  <NO_OTHER_FAILURES>
------------------------------------------------------------
Root Cause (first observed failure):
[0]:
  time      : 2025-05-20_10:32:31
  host      : node007.localdomain
  rank      : 5 (local_rank: 0)
  exitcode  : 1 (pid: 685102)
  error_file: <N/A>
  traceback : To enable traceback see: https://pytorch.org/docs/stable/elastic/errors.html
Traceback (most recent call last):
  File "/var/scratch/tng204/anaconda3/envs/mltrain/bin/torchrun", line 8, in <module>
============================================================
    return launch_agent(self._config, self._entrypoint, list(args))
  File "/var/scratch/tng204/anaconda3/envs/mltrain/lib/python3.10/site-packages/torch/distributed/launcher/api.py", line 245, in launch_agent
torch.distributed.elastic.multiprocessing.errors.ChildFailedError: 
============================================================
stable_char_transformer.py FAILED
------------------------------------------------------------
Failures:
  <NO_OTHER_FAILURES>
------------------------------------------------------------
Root Cause (first observed failure):
[0]:
  time      : 2025-05-20_10:32:31
  host      : node048.localdomain
  rank      : 11 (local_rank: 0)
  exitcode  : 1 (pid: 685346)
  error_file: <N/A>
  traceback : To enable traceback see: https://pytorch.org/docs/stable/elastic/errors.html
============================================================
    return f(*args, **kwargs)
    sys.exit(main())
    return f(*args, **kwargs)
  File "/var/scratch/tng204/anaconda3/envs/mltrain/lib/python3.10/site-packages/torch/distributed/run.py", line 761, in main
Traceback (most recent call last):
  File "/var/scratch/tng204/anaconda3/envs/mltrain/bin/torchrun", line 8, in <module>
    sys.exit(main())
  File "/var/scratch/tng204/anaconda3/envs/mltrain/lib/python3.10/site-packages/torch/distributed/elastic/multiprocessing/errors/__init__.py", line 345, in wrapper
    sys.exit(main())
  File "/var/scratch/tng204/anaconda3/envs/mltrain/lib/python3.10/site-packages/torch/distributed/elastic/multiprocessing/errors/__init__.py", line 345, in wrapper
Traceback (most recent call last):
  File "/var/scratch/tng204/anaconda3/envs/mltrain/bin/torchrun", line 8, in <module>
  File "/var/scratch/tng204/anaconda3/envs/mltrain/lib/python3.10/site-packages/torch/distributed/elastic/multiprocessing/errors/__init__.py", line 345, in wrapper
    sys.exit(main())
  File "/var/scratch/tng204/anaconda3/envs/mltrain/lib/python3.10/site-packages/torch/distributed/run.py", line 761, in main
    raise ChildFailedError(
    return f(*args, **kwargs)
  File "/var/scratch/tng204/anaconda3/envs/mltrain/lib/python3.10/site-packages/torch/distributed/run.py", line 761, in main
  File "/var/scratch/tng204/anaconda3/envs/mltrain/lib/python3.10/site-packages/torch/distributed/elastic/multiprocessing/errors/__init__.py", line 345, in wrapper
    return f(*args, **kwargs)
    return f(*args, **kwargs)
  File "/var/scratch/tng204/anaconda3/envs/mltrain/lib/python3.10/site-packages/torch/distributed/run.py", line 761, in main
torch.distributed.elastic.multiprocessing.errors.ChildFailedError: 
============================================================
stable_char_transformer.py FAILED
------------------------------------------------------------
Failures:
  <NO_OTHER_FAILURES>
------------------------------------------------------------
Root Cause (first observed failure):
[0]:
  time      : 2025-05-20_10:32:31
  host      : node051.localdomain
  rank      : 14 (local_rank: 0)
  exitcode  : 1 (pid: 702176)
  error_file: <N/A>
  traceback : To enable traceback see: https://pytorch.org/docs/stable/elastic/errors.html
  File "/var/scratch/tng204/anaconda3/envs/mltrain/lib/python3.10/site-packages/torch/distributed/run.py", line 761, in main
    sys.exit(main())
  File "/var/scratch/tng204/anaconda3/envs/mltrain/lib/python3.10/site-packages/torch/distributed/elastic/multiprocessing/errors/__init__.py", line 345, in wrapper
============================================================
    run(args)
  File "/var/scratch/tng204/anaconda3/envs/mltrain/lib/python3.10/site-packages/torch/distributed/run.py", line 752, in run
    sys.exit(main())
    return f(*args, **kwargs)
    return f(*args, **kwargs)
  File "/var/scratch/tng204/anaconda3/envs/mltrain/lib/python3.10/site-packages/torch/distributed/elastic/multiprocessing/errors/__init__.py", line 345, in wrapper
  File "/var/scratch/tng204/anaconda3/envs/mltrain/lib/python3.10/site-packages/torch/distributed/run.py", line 761, in main
  File "/var/scratch/tng204/anaconda3/envs/mltrain/lib/python3.10/site-packages/torch/distributed/run.py", line 761, in main
    return f(*args, **kwargs)
  File "/var/scratch/tng204/anaconda3/envs/mltrain/lib/python3.10/site-packages/torch/distributed/run.py", line 761, in main
    run(args)
  File "/var/scratch/tng204/anaconda3/envs/mltrain/lib/python3.10/site-packages/torch/distributed/run.py", line 752, in run
    sys.exit(main())
  File "/var/scratch/tng204/anaconda3/envs/mltrain/lib/python3.10/site-packages/torch/distributed/elastic/multiprocessing/errors/__init__.py", line 345, in wrapper
    run(args)
  File "/var/scratch/tng204/anaconda3/envs/mltrain/lib/python3.10/site-packages/torch/distributed/run.py", line 752, in run
    return f(*args, **kwargs)
  File "/var/scratch/tng204/anaconda3/envs/mltrain/lib/python3.10/site-packages/torch/distributed/run.py", line 761, in main
    return f(*args, **kwargs)
    run(args)
  File "/var/scratch/tng204/anaconda3/envs/mltrain/lib/python3.10/site-packages/torch/distributed/run.py", line 752, in run
  File "/var/scratch/tng204/anaconda3/envs/mltrain/lib/python3.10/site-packages/torch/distributed/run.py", line 761, in main
    return f(*args, **kwargs)
  File "/var/scratch/tng204/anaconda3/envs/mltrain/lib/python3.10/site-packages/torch/distributed/run.py", line 761, in main
    run(args)
  File "/var/scratch/tng204/anaconda3/envs/mltrain/lib/python3.10/site-packages/torch/distributed/run.py", line 752, in run
    run(args)
  File "/var/scratch/tng204/anaconda3/envs/mltrain/lib/python3.10/site-packages/torch/distributed/run.py", line 752, in run
    elastic_launch(
  File "/var/scratch/tng204/anaconda3/envs/mltrain/lib/python3.10/site-packages/torch/distributed/launcher/api.py", line 131, in __call__
    run(args)
  File "/var/scratch/tng204/anaconda3/envs/mltrain/lib/python3.10/site-packages/torch/distributed/run.py", line 752, in run
    return f(*args, **kwargs)
  File "/var/scratch/tng204/anaconda3/envs/mltrain/lib/python3.10/site-packages/torch/distributed/run.py", line 761, in main
    run(args)
  File "/var/scratch/tng204/anaconda3/envs/mltrain/lib/python3.10/site-packages/torch/distributed/run.py", line 752, in run
    elastic_launch(
  File "/var/scratch/tng204/anaconda3/envs/mltrain/lib/python3.10/site-packages/torch/distributed/launcher/api.py", line 131, in __call__
    elastic_launch(
  File "/var/scratch/tng204/anaconda3/envs/mltrain/lib/python3.10/site-packages/torch/distributed/launcher/api.py", line 131, in __call__
    run(args)
  File "/var/scratch/tng204/anaconda3/envs/mltrain/lib/python3.10/site-packages/torch/distributed/run.py", line 752, in run
    run(args)
  File "/var/scratch/tng204/anaconda3/envs/mltrain/lib/python3.10/site-packages/torch/distributed/run.py", line 752, in run
    return launch_agent(self._config, self._entrypoint, list(args))
  File "/var/scratch/tng204/anaconda3/envs/mltrain/lib/python3.10/site-packages/torch/distributed/launcher/api.py", line 245, in launch_agent
    run(args)
  File "/var/scratch/tng204/anaconda3/envs/mltrain/lib/python3.10/site-packages/torch/distributed/run.py", line 752, in run
    elastic_launch(
  File "/var/scratch/tng204/anaconda3/envs/mltrain/lib/python3.10/site-packages/torch/distributed/launcher/api.py", line 131, in __call__
    return launch_agent(self._config, self._entrypoint, list(args))
  File "/var/scratch/tng204/anaconda3/envs/mltrain/lib/python3.10/site-packages/torch/distributed/launcher/api.py", line 245, in launch_agent
    run(args)
    return launch_agent(self._config, self._entrypoint, list(args))
  File "/var/scratch/tng204/anaconda3/envs/mltrain/lib/python3.10/site-packages/torch/distributed/launcher/api.py", line 245, in launch_agent
    elastic_launch(
  File "/var/scratch/tng204/anaconda3/envs/mltrain/lib/python3.10/site-packages/torch/distributed/run.py", line 752, in run
    raise ChildFailedError(
torch.distributed.elastic.multiprocessing.errors.ChildFailedError: 
============================================================
stable_char_transformer.py FAILED
------------------------------------------------------------
Failures:
  <NO_OTHER_FAILURES>
------------------------------------------------------------
Root Cause (first observed failure):
[0]:
  time      : 2025-05-20_10:32:26
  host      : node002.localdomain
  rank      : 0 (local_rank: 0)
  exitcode  : 1 (pid: 837761)
  error_file: <N/A>
  traceback : To enable traceback see: https://pytorch.org/docs/stable/elastic/errors.html
============================================================
  File "/var/scratch/tng204/anaconda3/envs/mltrain/lib/python3.10/site-packages/torch/distributed/launcher/api.py", line 131, in __call__
    elastic_launch(
  File "/var/scratch/tng204/anaconda3/envs/mltrain/lib/python3.10/site-packages/torch/distributed/launcher/api.py", line 131, in __call__
    elastic_launch(
  File "/var/scratch/tng204/anaconda3/envs/mltrain/lib/python3.10/site-packages/torch/distributed/launcher/api.py", line 131, in __call__
    raise ChildFailedError(
    return launch_agent(self._config, self._entrypoint, list(args))
  File "/var/scratch/tng204/anaconda3/envs/mltrain/lib/python3.10/site-packages/torch/distributed/launcher/api.py", line 245, in launch_agent
    elastic_launch(
  File "/var/scratch/tng204/anaconda3/envs/mltrain/lib/python3.10/site-packages/torch/distributed/launcher/api.py", line 131, in __call__
    raise ChildFailedError(
torch.distributed.elastic.multiprocessing.errors.ChildFailedError: 
============================================================
stable_char_transformer.py FAILED
------------------------------------------------------------
Failures:
  <NO_OTHER_FAILURES>
------------------------------------------------------------
Root Cause (first observed failure):
[0]:
  time      : 2025-05-20_10:32:31
  host      : node004.localdomain
  rank      : 2 (local_rank: 0)
  exitcode  : 1 (pid: 782908)
  error_file: <N/A>
  traceback : To enable traceback see: https://pytorch.org/docs/stable/elastic/errors.html
    run(args)
  File "/var/scratch/tng204/anaconda3/envs/mltrain/lib/python3.10/site-packages/torch/distributed/run.py", line 752, in run
============================================================
    return launch_agent(self._config, self._entrypoint, list(args))
  File "/var/scratch/tng204/anaconda3/envs/mltrain/lib/python3.10/site-packages/torch/distributed/launcher/api.py", line 245, in launch_agent
    return launch_agent(self._config, self._entrypoint, list(args))
torch.distributed.elastic.multiprocessing.errors.ChildFailedError: 
============================================================
stable_char_transformer.py FAILED
------------------------------------------------------------
Failures:
  <NO_OTHER_FAILURES>
------------------------------------------------------------
Root Cause (first observed failure):
[0]:
  time      : 2025-05-20_10:32:31
  host      : node052.localdomain
  rank      : 15 (local_rank: 0)
  exitcode  : 1 (pid: 696363)
  error_file: <N/A>
  traceback : To enable traceback see: https://pytorch.org/docs/stable/elastic/errors.html
============================================================
    return launch_agent(self._config, self._entrypoint, list(args))
  File "/var/scratch/tng204/anaconda3/envs/mltrain/lib/python3.10/site-packages/torch/distributed/launcher/api.py", line 245, in launch_agent
    elastic_launch(
  File "/var/scratch/tng204/anaconda3/envs/mltrain/lib/python3.10/site-packages/torch/distributed/launcher/api.py", line 131, in __call__
    raise ChildFailedError(
  File "/var/scratch/tng204/anaconda3/envs/mltrain/lib/python3.10/site-packages/torch/distributed/launcher/api.py", line 245, in launch_agent
    return launch_agent(self._config, self._entrypoint, list(args))
    elastic_launch(
  File "/var/scratch/tng204/anaconda3/envs/mltrain/lib/python3.10/site-packages/torch/distributed/launcher/api.py", line 131, in __call__
torch.distributed.elastic.multiprocessing.errors.ChildFailedError: 
============================================================
stable_char_transformer.py FAILED
------------------------------------------------------------
Failures:
  <NO_OTHER_FAILURES>
------------------------------------------------------------
Root Cause (first observed failure):
[0]:
  time      : 2025-05-20_10:32:31
  host      : node006.localdomain
  rank      : 4 (local_rank: 0)
  exitcode  : 1 (pid: 716542)
  error_file: <N/A>
  traceback : To enable traceback see: https://pytorch.org/docs/stable/elastic/errors.html
    elastic_launch(
============================================================
    raise ChildFailedError(
  File "/var/scratch/tng204/anaconda3/envs/mltrain/lib/python3.10/site-packages/torch/distributed/launcher/api.py", line 245, in launch_agent
    raise ChildFailedError(
torch.distributed.elastic.multiprocessing.errors.ChildFailedError: 
============================================================
stable_char_transformer.py FAILED
------------------------------------------------------------
Failures:
  <NO_OTHER_FAILURES>
------------------------------------------------------------
Root Cause (first observed failure):
[0]:
  time      : 2025-05-20_10:32:31
  host      : node025.localdomain
  rank      : 7 (local_rank: 0)
  exitcode  : 1 (pid: 1006903)
  error_file: <N/A>
  traceback : To enable traceback see: https://pytorch.org/docs/stable/elastic/errors.html
============================================================
    raise ChildFailedError(
  File "/var/scratch/tng204/anaconda3/envs/mltrain/lib/python3.10/site-packages/torch/distributed/launcher/api.py", line 131, in __call__
    elastic_launch(
    raise ChildFailedError(
    return launch_agent(self._config, self._entrypoint, list(args))
  File "/var/scratch/tng204/anaconda3/envs/mltrain/lib/python3.10/site-packages/torch/distributed/launcher/api.py", line 245, in launch_agent
    return launch_agent(self._config, self._entrypoint, list(args))
  File "/var/scratch/tng204/anaconda3/envs/mltrain/lib/python3.10/site-packages/torch/distributed/launcher/api.py", line 245, in launch_agent
torch.distributed.elastic.multiprocessing.errors.ChildFailedError: 
============================================================
stable_char_transformer.py FAILED
------------------------------------------------------------
Failures:
  <NO_OTHER_FAILURES>
------------------------------------------------------------
Root Cause (first observed failure):
[0]:
  time      : 2025-05-20_10:32:31
  host      : node049.localdomain
  rank      : 12 (local_rank: 0)
  exitcode  : 1 (pid: 672612)
  error_file: <N/A>
  traceback : To enable traceback see: https://pytorch.org/docs/stable/elastic/errors.html
============================================================
torch.distributed.elastic.multiprocessing.errors.ChildFailedError: 
============================================================
stable_char_transformer.py FAILED
------------------------------------------------------------
Failures:
  <NO_OTHER_FAILURES>
------------------------------------------------------------
Root Cause (first observed failure):
[0]:
  time      : 2025-05-20_10:32:31
  host      : node003.localdomain
  rank      : 1 (local_rank: 0)
  exitcode  : 1 (pid: 804448)
  error_file: <N/A>
  traceback : To enable traceback see: https://pytorch.org/docs/stable/elastic/errors.html
============================================================
torch.distributed.elastic.multiprocessing.errors.ChildFailedError: 
============================================================
stable_char_transformer.py FAILED
------------------------------------------------------------
Failures:
  <NO_OTHER_FAILURES>
------------------------------------------------------------
Root Cause (first observed failure):
[0]:
  time      : 2025-05-20_10:32:31
  host      : node050.localdomain
  rank      : 13 (local_rank: 0)
  exitcode  : 1 (pid: 703615)
  error_file: <N/A>
  traceback : To enable traceback see: https://pytorch.org/docs/stable/elastic/errors.html
============================================================
  File "/var/scratch/tng204/anaconda3/envs/mltrain/lib/python3.10/site-packages/torch/distributed/launcher/api.py", line 131, in __call__
    elastic_launch(
  File "/var/scratch/tng204/anaconda3/envs/mltrain/lib/python3.10/site-packages/torch/distributed/launcher/api.py", line 131, in __call__
    return launch_agent(self._config, self._entrypoint, list(args))
  File "/var/scratch/tng204/anaconda3/envs/mltrain/lib/python3.10/site-packages/torch/distributed/launcher/api.py", line 245, in launch_agent
    return launch_agent(self._config, self._entrypoint, list(args))
    raise ChildFailedError(
  File "/var/scratch/tng204/anaconda3/envs/mltrain/lib/python3.10/site-packages/torch/distributed/launcher/api.py", line 245, in launch_agent
torch.distributed.elastic.multiprocessing.errors.ChildFailedError: 
============================================================
stable_char_transformer.py FAILED
------------------------------------------------------------
Failures:
  <NO_OTHER_FAILURES>
------------------------------------------------------------
Root Cause (first observed failure):
[0]:
  time      : 2025-05-20_10:32:31
  host      : node047.localdomain
  rank      : 10 (local_rank: 0)
  exitcode  : 1 (pid: 705116)
  error_file: <N/A>
  traceback : To enable traceback see: https://pytorch.org/docs/stable/elastic/errors.html
============================================================
    raise ChildFailedError(
    raise ChildFailedError(
torch.distributed.elastic.multiprocessing.errors.ChildFailedError: 
============================================================
stable_char_transformer.py FAILED
------------------------------------------------------------
Failures:
  <NO_OTHER_FAILURES>
------------------------------------------------------------
Root Cause (first observed failure):
[0]:
  time      : 2025-05-20_10:32:31
  host      : node024.localdomain
  rank      : 6 (local_rank: 0)
  exitcode  : 1 (pid: 3578907)
  error_file: <N/A>
  traceback : To enable traceback see: https://pytorch.org/docs/stable/elastic/errors.html
    return launch_agent(self._config, self._entrypoint, list(args))
  File "/var/scratch/tng204/anaconda3/envs/mltrain/lib/python3.10/site-packages/torch/distributed/launcher/api.py", line 245, in launch_agent
============================================================
torch.distributed.elastic.multiprocessing.errors.ChildFailedError: 
============================================================
stable_char_transformer.py FAILED
------------------------------------------------------------
Failures:
  <NO_OTHER_FAILURES>
------------------------------------------------------------
Root Cause (first observed failure):
[0]:
  time      : 2025-05-20_10:32:31
  host      : node005.localdomain
  rank      : 3 (local_rank: 0)
  exitcode  : 1 (pid: 814951)
  error_file: <N/A>
  traceback : To enable traceback see: https://pytorch.org/docs/stable/elastic/errors.html
============================================================
    raise ChildFailedError(
    raise ChildFailedError(
torch.distributed.elastic.multiprocessing.errors.ChildFailedError: 
============================================================
stable_char_transformer.py FAILED
------------------------------------------------------------
Failures:
  <NO_OTHER_FAILURES>
------------------------------------------------------------
Root Cause (first observed failure):
[0]:
  time      : 2025-05-20_10:32:31
  host      : node026.localdomain
  rank      : 8 (local_rank: 0)
  exitcode  : 1 (pid: 700923)
  error_file: <N/A>
  traceback : To enable traceback see: https://pytorch.org/docs/stable/elastic/errors.html
============================================================
torch.distributed.elastic.multiprocessing.errors.ChildFailedError: 
============================================================
stable_char_transformer.py FAILED
------------------------------------------------------------
Failures:
  <NO_OTHER_FAILURES>
------------------------------------------------------------
Root Cause (first observed failure):
[0]:
  time      : 2025-05-20_10:32:31
  host      : node046.localdomain
  rank      : 9 (local_rank: 0)
  exitcode  : 1 (pid: 723800)
  error_file: <N/A>
  traceback : To enable traceback see: https://pytorch.org/docs/stable/elastic/errors.html
============================================================
srun: error: node050: task 13: Exited with exit code 1
srun: Terminating StepId=25663.0
srun: error: node048: task 11: Exited with exit code 1
srun: error: node006: task 4: Exited with exit code 1
srun: error: node025: task 7: Exited with exit code 1
slurmstepd-node002: error: *** STEP 25663.0 ON node002 CANCELLED AT 2025-05-20T10:32:31 ***
srun: error: node046: task 9: Exited with exit code 1
srun: error: node051: task 14: Exited with exit code 1
srun: error: node049: task 12: Exited with exit code 1
srun: error: node047: task 10: Exited with exit code 1
srun: error: node052: task 15: Exited with exit code 1
srun: error: node007: task 5: Exited with exit code 1
srun: error: node024: task 6: Exited with exit code 1
srun: error: node005: task 3: Exited with exit code 1
srun: error: node002: task 0: Exited with exit code 1
srun: error: node026: task 8: Terminated
srun: error: node004: task 2: Exited with exit code 1
srun: error: node003: task 1: Terminated
srun: Force Terminated StepId=25663.0
